2018-12-29 18:59:01 connectionpool.py [line:208] DEBUG: Starting new HTTP connection (1): 202.104.113.35
2018-12-29 18:59:02 connectionpool.py [line:396] DEBUG: http://202.104.113.35:53281 "GET http://httpbin.org/get HTTP/1.1" 200 443
2018-12-29 18:59:02 connectionpool.py [line:824] DEBUG: Starting new HTTPS connection (1): httpbin.org
2018-12-29 18:59:06 connectionpool.py [line:396] DEBUG: https://httpbin.org:443 "GET /get HTTP/1.1" 200 439
2018-12-29 18:59:55 connectionpool.py [line:208] DEBUG: Starting new HTTP connection (1): 61.135.217.7
2018-12-29 18:59:55 connectionpool.py [line:396] DEBUG: http://61.135.217.7:80 "GET http://httpbin.org/get HTTP/1.1" 301 230
2018-12-29 18:59:55 connectionpool.py [line:396] DEBUG: http://61.135.217.7:80 "GET http://www.youdao.com/ HTTP/1.1" 200 None
2018-12-29 18:59:55 httpbin_validator.py [line:102] ERROR: Expecting value: line 1 column 1 (char 0)
Traceback (most recent call last):
  File "/Users/itheima/Desktop/N+12课程/代理池/code/IPProxyPool/core/proxy_validate/httpbin_validator.py", line 85, in __check_http_proxies
    dic = json.loads(response.text)
  File "/usr/local/Cellar/python/3.7.1/Frameworks/Python.framework/Versions/3.7/lib/python3.7/json/__init__.py", line 348, in loads
    return _default_decoder.decode(s)
  File "/usr/local/Cellar/python/3.7.1/Frameworks/Python.framework/Versions/3.7/lib/python3.7/json/decoder.py", line 337, in decode
    obj, end = self.raw_decode(s, idx=_w(s, 0).end())
  File "/usr/local/Cellar/python/3.7.1/Frameworks/Python.framework/Versions/3.7/lib/python3.7/json/decoder.py", line 355, in raw_decode
    raise JSONDecodeError("Expecting value", s, err.value) from None
json.decoder.JSONDecodeError: Expecting value: line 1 column 1 (char 0)
2018-12-29 18:59:55 connectionpool.py [line:824] DEBUG: Starting new HTTPS connection (1): httpbin.org
2018-12-29 18:59:55 httpbin_validator.py [line:102] ERROR: HTTPSConnectionPool(host='httpbin.org', port=443): Max retries exceeded with url: /get (Caused by ProxyError('Cannot connect to proxy.', OSError('Tunnel connection failed: 400 Bad Request')))
Traceback (most recent call last):
  File "/usr/local/lib/python3.7/site-packages/urllib3/connectionpool.py", line 595, in urlopen
    self._prepare_proxy(conn)
  File "/usr/local/lib/python3.7/site-packages/urllib3/connectionpool.py", line 816, in _prepare_proxy
    conn.connect()
  File "/usr/local/lib/python3.7/site-packages/urllib3/connection.py", line 294, in connect
    self._tunnel()
  File "/usr/local/Cellar/python/3.7.1/Frameworks/Python.framework/Versions/3.7/lib/python3.7/http/client.py", line 911, in _tunnel
    message.strip()))
OSError: Tunnel connection failed: 400 Bad Request

During handling of the above exception, another exception occurred:

Traceback (most recent call last):
  File "/usr/local/lib/python3.7/site-packages/requests/adapters.py", line 440, in send
    timeout=timeout
  File "/usr/local/lib/python3.7/site-packages/urllib3/connectionpool.py", line 639, in urlopen
    _stacktrace=sys.exc_info()[2])
  File "/usr/local/lib/python3.7/site-packages/urllib3/util/retry.py", line 388, in increment
    raise MaxRetryError(_pool, url, error or ResponseError(cause))
urllib3.exceptions.MaxRetryError: HTTPSConnectionPool(host='httpbin.org', port=443): Max retries exceeded with url: /get (Caused by ProxyError('Cannot connect to proxy.', OSError('Tunnel connection failed: 400 Bad Request')))

During handling of the above exception, another exception occurred:

Traceback (most recent call last):
  File "/Users/itheima/Desktop/N+12课程/代理池/code/IPProxyPool/core/proxy_validate/httpbin_validator.py", line 78, in __check_http_proxies
    response = requests.get(test_url, headers=get_request_headers(), proxies=proxies, timeout=TEST_TIMEOUT)
  File "/usr/local/lib/python3.7/site-packages/requests/api.py", line 72, in get
    return request('get', url, params=params, **kwargs)
  File "/usr/local/lib/python3.7/site-packages/requests/api.py", line 58, in request
    return session.request(method=method, url=url, **kwargs)
  File "/usr/local/lib/python3.7/site-packages/requests/sessions.py", line 508, in request
    resp = self.send(prep, **send_kwargs)
  File "/usr/local/lib/python3.7/site-packages/requests/sessions.py", line 618, in send
    r = adapter.send(request, **kwargs)
  File "/usr/local/lib/python3.7/site-packages/requests/adapters.py", line 502, in send
    raise ProxyError(e, request=request)
requests.exceptions.ProxyError: HTTPSConnectionPool(host='httpbin.org', port=443): Max retries exceeded with url: /get (Caused by ProxyError('Cannot connect to proxy.', OSError('Tunnel connection failed: 400 Bad Request')))
